[2022-09-09 09:09:33,962] {taskinstance.py:877} INFO - Dependencies all met for <TaskInstance: trip_etl.ssh_task 2022-09-09T09:09:32.969178+00:00 [queued]>
[2022-09-09 09:09:33,969] {taskinstance.py:877} INFO - Dependencies all met for <TaskInstance: trip_etl.ssh_task 2022-09-09T09:09:32.969178+00:00 [queued]>
[2022-09-09 09:09:33,969] {taskinstance.py:1068} INFO - 
--------------------------------------------------------------------------------
[2022-09-09 09:09:33,969] {taskinstance.py:1069} INFO - Starting attempt 1 of 1
[2022-09-09 09:09:33,970] {taskinstance.py:1070} INFO - 
--------------------------------------------------------------------------------
[2022-09-09 09:09:33,980] {taskinstance.py:1089} INFO - Executing <Task(SSHOperator): ssh_task> on 2022-09-09T09:09:32.969178+00:00
[2022-09-09 09:09:33,983] {standard_task_runner.py:52} INFO - Started process 56 to run task
[2022-09-09 09:09:33,986] {standard_task_runner.py:76} INFO - Running: ['airflow', 'tasks', 'run', 'trip_etl', 'ssh_task', '2022-09-09T09:09:32.969178+00:00', '--job-id', '85', '--pool', 'default_pool', '--raw', '--subdir', 'DAGS_FOLDER/clickhouse test.py', '--cfg-path', '/tmp/tmpezaj9pu9', '--error-file', '/tmp/tmpsqwb0w77']
[2022-09-09 09:09:33,986] {standard_task_runner.py:77} INFO - Job 85: Subtask ssh_task
[2022-09-09 09:09:34,016] {logging_mixin.py:104} INFO - Running <TaskInstance: trip_etl.ssh_task 2022-09-09T09:09:32.969178+00:00 [running]> on host 3f125d5f6fbd
[2022-09-09 09:09:34,042] {taskinstance.py:1283} INFO - Exporting the following env vars:
AIRFLOW_CTX_DAG_OWNER=airflow
AIRFLOW_CTX_DAG_ID=trip_etl
AIRFLOW_CTX_TASK_ID=ssh_task
AIRFLOW_CTX_EXECUTION_DATE=2022-09-09T09:09:32.969178+00:00
AIRFLOW_CTX_DAG_RUN_ID=manual__2022-09-09T09:09:32.969178+00:00
[2022-09-09 09:09:34,043] {ssh.py:91} INFO - ssh_hook is not provided or invalid. Trying ssh_conn_id to create SSHHook.
[2022-09-09 09:09:34,048] {base.py:78} INFO - Using connection to: id: nfrssh. Host: 192.168.16.1, Port: 22, Schema: , Login: nfrs, Password: XXXXXXXX, extra: XXXXXXXX
[2022-09-09 09:09:34,048] {ssh.py:204} WARNING - Remote Identification Change is not verified. This wont protect against Man-In-The-Middle attacks
[2022-09-09 09:09:34,049] {ssh.py:210} WARNING - No Host Key Verification. This wont protect against Man-In-The-Middle attacks
[2022-09-09 09:09:44,058] {taskinstance.py:1482} ERROR - Task failed with exception
Traceback (most recent call last):
  File "/home/airflow/.local/lib/python3.6/site-packages/airflow/providers/ssh/operators/ssh.py", line 109, in execute
    with self.ssh_hook.get_conn() as ssh_client:
  File "/home/airflow/.local/lib/python3.6/site-packages/airflow/providers/ssh/hooks/ssh.py", line 240, in get_conn
    client.connect(**connect_kwargs)
  File "/home/airflow/.local/lib/python3.6/site-packages/paramiko/client.py", line 349, in connect
    retry_on_signal(lambda: sock.connect(addr))
  File "/home/airflow/.local/lib/python3.6/site-packages/paramiko/util.py", line 283, in retry_on_signal
    return function()
  File "/home/airflow/.local/lib/python3.6/site-packages/paramiko/client.py", line 349, in <lambda>
    retry_on_signal(lambda: sock.connect(addr))
socket.timeout: timed out

During handling of the above exception, another exception occurred:

Traceback (most recent call last):
  File "/home/airflow/.local/lib/python3.6/site-packages/airflow/models/taskinstance.py", line 1138, in _run_raw_task
    self._prepare_and_execute_task_with_callbacks(context, task)
  File "/home/airflow/.local/lib/python3.6/site-packages/airflow/models/taskinstance.py", line 1311, in _prepare_and_execute_task_with_callbacks
    result = self._execute_task(context, task_copy)
  File "/home/airflow/.local/lib/python3.6/site-packages/airflow/models/taskinstance.py", line 1341, in _execute_task
    result = task_copy.execute(context=context)
  File "/home/airflow/.local/lib/python3.6/site-packages/airflow/providers/ssh/operators/ssh.py", line 172, in execute
    raise AirflowException(f"SSH operator error: {str(e)}")
airflow.exceptions.AirflowException: SSH operator error: timed out
[2022-09-09 09:09:44,062] {taskinstance.py:1532} INFO - Marking task as FAILED. dag_id=trip_etl, task_id=ssh_task, execution_date=20220909T090932, start_date=20220909T090933, end_date=20220909T090944
[2022-09-09 09:09:44,092] {local_task_job.py:146} INFO - Task exited with return code 1
